<robot
  name="Arcus">
	<mujoco>
		<compiler meshdir="meshes/" discardvisual="false"/>
	</mujoco>

  <!-- [CAUTION] uncomment when convert to mujoco -->
  <!-- <link name="world"></link>
  <joint name="floating_base_joint" type="floating">
    <parent link="world"/>
    <child link="pelvis"/>
  </joint> -->

  <link
    name="pelvis">
    <inertial>
      <origin
        xyz="-1.0044E-07 0.0645 0.02807"
        rpy="0 0 0" />
      <mass
        value="4.806" />
      <inertia
        ixx="0.012426"
        ixy="1.9456E-08"
        ixz="-1.9001E-08"
        iyy="0.0099675"
        iyz="-1.5778E-08"
        izz="0.0086797" />
    </inertial>
    <visual>
      <origin
        xyz="0 0 0"
        rpy="0 0 0" />
      <geometry>
        <mesh
          filename="meshes/pelvis.STL" />
      </geometry>
      <material
        name="">
        <color
          rgba="0.75294 0.75294 0.75294 1" />
      </material>
    </visual>
    <collision>
      <origin
        xyz="0 0 0"
        rpy="0 0 0" />
      <geometry>
        <mesh
          filename="meshes/pelvis.STL" />
      </geometry>
    </collision>
  </link>

	<!-- Legs -->
	<link
  name="left_hip_pitch_link">
		<inertial>
			<origin
			  xyz="0.0050315 0.050932 -0.028937"
			  rpy="0 0 0" />
			<mass
			  value="1.3923" />
			<inertia
			  ixx="0.0011976"
			  ixy="-6.8805E-06"
			  ixz="5.422E-05"
			  iyy="0.0010846"
			  iyz="1.5164E-05"
			  izz="0.00085463" />
		</inertial>
		<visual>
			<origin
			  xyz="0 0 0"
			  rpy="0 0 0" />
			<geometry>
				<mesh
				  filename="meshes/left_hip_pitch_link.STL" />
			</geometry>
			<material
			  name="">
				<color
				  rgba="0.75294 0.75294 0.75294 1" />
			</material>
		</visual>
		<collision>
			<origin
			  xyz="0 0 0"
			  rpy="0 0 0" />
			<geometry>
				<mesh
				  filename="meshes/left_hip_pitch_link.STL" />
			</geometry>
		</collision>
	</link>
	<joint
	  name="left_hip_pitch_joint"
	  type="revolute">
		<origin
		  xyz="0 0.129 0"
		  rpy="0 0 0" />
		<parent
		  link="pelvis" />
		<child
		  link="left_hip_pitch_link" />
		<axis
		  xyz="0 1 0" />
		<limit
		  lower="-2.5307"
		  upper="2.8798"
		  effort="88"
		  velocity="32" />
		<dynamics
		  damping="0.001"
		  friction="0.1" />
	</joint>
	<link
	  name="left_hip_roll_link">
		<inertial>
			<origin
			  xyz="-0.014682 -0.0012851 -0.11682"
			  rpy="0 0 0" />
			<mass
			  value="1.4711" />
			<inertia
			  ixx="0.0020528"
			  ixy="-4.2446E-07"
			  ixz="7.1184E-06"
			  iyy="0.0017981"
			  iyz="-7.1461E-06"
			  izz="0.0011948" />
		</inertial>
		<visual>
			<origin
			  xyz="0 0 0"
			  rpy="0 0 0" />
			<geometry>
				<mesh
				  filename="meshes/left_hip_roll_link.STL" />
			</geometry>
			<material
			  name="">
				<color
				  rgba="0.75294 0.75294 0.75294 1" />
			</material>
		</visual>
		<!-- <collision>
			<origin
			  xyz="0 0 0"
			  rpy="0 0 0" />
			<geometry>
				<mesh
				  filename="meshes/left_hip_roll_link.STL" />
			</geometry>
		</collision> -->
	</link>
	<joint
	  name="left_hip_roll_joint"
	  type="revolute">
		<origin
		  xyz="0.0331118430306477 0.0519845204764553 -0.0243891056337236"
		  rpy="0 0 0" />
		<parent
		  link="left_hip_pitch_link" />
		<child
		  link="left_hip_roll_link" />
		<axis
		  xyz="0.983751487188846 0 0.179535543705789" />
		<limit lower="-0.5236" upper="2.9671" effort="139" velocity="20"/>
		<dynamics
		  damping="0.001"
		  friction="0.1" />
	</joint>
	<link
	  name="left_hip_yaw_link">
		<inertial>
			<origin
			  xyz="-0.002876 -0.011686 -0.16915"
			  rpy="0 0 0" />
			<mass
			  value="1.7026" />
			<inertia
			  ixx="0.0016049"
			  ixy="1.3296E-05"
			  ixz="-4.2787E-05"
			  iyy="0.0018168"
			  iyz="-3.7527E-05"
			  izz="0.0011713" />
		</inertial>
		<visual>
			<origin
			  xyz="0 0 0"
			  rpy="0 0 0" />
			<geometry>
				<mesh
				  filename="meshes/left_hip_yaw_link.STL" />
			</geometry>
			<material
			  name="">
				<color
				  rgba="0.75294 0.75294 0.75294 1" />
			</material>
		</visual>
		<collision>
			<origin
			  xyz="0 0 0"
			  rpy="0 0 0" />
			<geometry>
				<mesh
				  filename="meshes/left_hip_yaw_link.STL" />
			</geometry>
		</collision>
	</link>
	<joint
	  name="left_hip_yaw_joint"
	  type="revolute">
		<origin
		  xyz="-0.0131193804231179 -0.00177325411006572 -0.160642296736502"
		  rpy="0 0 0" />
		<parent
		  link="left_hip_roll_link" />
		<child
		  link="left_hip_yaw_link" />
		<axis
		  xyz="-0.179524878941636 0.0108995597223406 0.983693050417075" />
		<limit
		  lower="-2.7576"
		  upper="2.7576"
		  effort="88"
		  velocity="32" />
		<dynamics
		  damping="0.001"
		  friction="0.1" />
	</joint>
	<link
	  name="left_knee_link">
		<inertial>
			<origin
			  xyz="0.0061721 -0.017424 -0.15995"
			  rpy="0 0 0" />
			<mass
			  value="2.1905" />
			<inertia
			  ixx="0.0096767"
			  ixy="6.0818E-06"
			  ixz="-6.3088E-06"
			  iyy="0.0098856"
			  iyz="-0.00012642"
			  izz="0.0012629" />
		</inertial>
		<visual>
			<origin
			  xyz="0 0 0"
			  rpy="0 0 0" />
			<geometry>
				<mesh
				  filename="meshes/left_knee_link.STL" />
			</geometry>
			<material
			  name="">
				<color
				  rgba="0.75294 0.75294 0.75294 1" />
			</material>
		</visual>
		<collision>
			<origin
			  xyz="0 0 0"
			  rpy="0 0 0" />
			<geometry>
				<mesh
				  filename="meshes/left_knee_link.STL" />
			</geometry>
		</collision>
	</link>
	<joint
	  name="left_knee_joint"
	  type="revolute">
		<origin
		  xyz="-0.00551150756522208 0.0150938599727033 -0.211323722706038"
		  rpy="0 0 0" />
		<parent
		  link="left_hip_yaw_link" />
		<child
		  link="left_knee_link" />
		<axis
		  xyz="0.00197977867350144 0.999940542975982 -0.0107233851605998" />
		<limit
		  lower="-0.0873"
		  upper="2.8798"
		  effort="139"
		  velocity="20" />
		<dynamics
		  damping="0.001"
		  friction="0.1" />
	</joint>
	<link
	  name="left_ankle_pitch_link">
		<inertial>
			<origin
			  xyz="-0.00639266478705468 -0.000103937147959504 -0.0108229813997331"
			  rpy="0 0 0" />
			<mass
			  value="0.0267996226956392" />
			<inertia
			  ixx="3.15001547743769E-06"
			  ixy="-3.48669796959445E-09"
			  ixz="-9.94614963226291E-07"
			  iyy="6.8796412203451E-06"
			  iyz="-2.42320441935354E-08"
			  izz="4.44568942948615E-06" />
		</inertial>
		<visual>
			<origin
			  xyz="0 0 0"
			  rpy="0 0 0" />
			<geometry>
				<mesh
				  filename="meshes/left_ankle_pitch_link.STL" />
			</geometry>
			<material
			  name="">
				<color
				  rgba="0.592156862745098 0.619607843137255 0.650980392156863 1" />
			</material>
		</visual>
		<!-- <collision>
			<origin
			  xyz="0 0 0"
			  rpy="0 0 0" />
			<geometry>
				<mesh
				  filename="meshes/left_ankle_pitch_link.STL" />
			</geometry>
		</collision> -->
	</link>
	<joint
	  name="left_ankle_pitch_joint"
	  type="revolute">
		<origin
		  xyz="0.00201288124086141 -0.0191183987820954 -0.344815668798164"
		  rpy="0 0 0" />
		<parent
		  link="left_knee_link" />
		<child
		  link="left_ankle_pitch_link" />
		<axis
		  xyz="0.00192988201521745 0.999940435649834 -0.0107424721469429" />
		<limit
		  lower="-0.8727"
		  upper="0.5236"
		  effort="50"
		  velocity="37" />
		<dynamics
		  damping="0.001"
		  friction="0.1" />
	</joint>
	<link
	  name="left_ankle_roll_link">
		<inertial>
			<origin
			  xyz="0.0742711838080633 0.00114688763747424 -0.0227870052157542"
			  rpy="0 0 0" />
			<mass
			  value="0.661710989570844" />
			<inertia
			  ixx="0.000331858931232205"
			  ixy="1.35372151359361E-05"
			  ixz="3.66012813590442E-05"
			  iyy="0.00234939767804801"
			  iyz="3.57896305952223E-06"
			  izz="0.0025682257032422" />
		</inertial>
		<visual>
			<origin
			  xyz="0 0 0"
			  rpy="0 0 0" />
			<geometry>
				<mesh
				  filename="meshes/left_ankle_roll_link.STL" />
			</geometry>
			<material
			  name="">
				<color
				  rgba="0.752941176470588 0.752941176470588 0.752941176470588 1" />
			</material>
		</visual>
	<collision>
      <origin xyz="-0.026 0.02 -0.04" rpy="0 0 0"/>
      <geometry>
        <sphere radius="0.005"/>
      </geometry>
    </collision>
    <collision>
      <origin xyz="-0.026 -0.025 -0.04" rpy="0 0 0"/>
      <geometry>
        <sphere radius="0.005"/>
      </geometry>
    </collision>
    <collision>
      <origin xyz="0.19 0.02 -0.04" rpy="0 0 0"/>
      <geometry>
        <sphere radius="0.005"/>
      </geometry>
    </collision>
    <collision>
      <origin xyz="0.19 -0.03 -0.04" rpy="0 0 0"/>
      <geometry>
        <sphere radius="0.005"/>
      </geometry>
    </collision>
	<!-- 	<collision>
			<origin
			  xyz="0 0 0"
			  rpy="0 0 0" />
			<geometry>
				<mesh
				  filename="meshes/left_ankle_roll_link.STL" />
			</geometry>
		</collision> -->
	</link>
	<joint
	  name="left_ankle_roll_joint"
	  type="revolute">
		<origin
		  xyz="-0.0267502390941501 -0.000141738323757093 -0.017999086606086"
		  rpy="0 0 0" />
		<parent
		  link="left_ankle_pitch_link" />
		<child
		  link="left_ankle_roll_link" />
		<axis
		  xyz="0.999998137647158 -0.00192994308100041 0" />
		<limit
		  lower="-0.2618"
		  upper="0.2618"
		  effort="50"
		  velocity="37" />
		<dynamics
		  damping="0.001"
		  friction="0.1" />
	</joint>
	
	<link
	  name="right_hip_pitch_link">
		<inertial>
			<origin
			  xyz="0.0050315 -0.050932 -0.028937"
			  rpy="0 0 0" />
			<mass
			  value="1.3923" />
			<inertia
			  ixx="0.0011976"
			  ixy="6.8804E-06"
			  ixz="5.4221E-05"
			  iyy="0.0010846"
			  iyz="-1.5164E-05"
			  izz="0.00085463" />
		</inertial>
		<visual>
			<origin
			  xyz="0 0 0"
			  rpy="0 0 0" />
			<geometry>
				<mesh
				  filename="meshes/right_hip_pitch_link.STL" />
			</geometry>
			<material
			  name="">
				<color
				  rgba="0.75294 0.75294 0.75294 1" />
			</material>
		</visual>
		<collision>
			<origin
			  xyz="0 0 0"
			  rpy="0 0 0" />
			<geometry>
				<mesh
				  filename="meshes/right_hip_pitch_link.STL" />
			</geometry>
		</collision>
	</link>
	<joint
	  name="right_hip_pitch_joint"
	  type="revolute">
		<origin
		  xyz="0 0 0"
		  rpy="0 0 0" />
		<parent
		  link="pelvis" />
		<child
		  link="right_hip_pitch_link" />
		<axis
		  xyz="0 -1 0" />
		<limit
		  lower="-2.5307"
		  upper="2.8798"
		  effort="88"
		  velocity="32" />
		<dynamics
		  damping="0.001"
		  friction="0.1" />
	</joint>
	<link
	  name="right_hip_roll_link">
		<inertial>
			<origin
			  xyz="-0.014681 -0.0011606 -0.11682"
			  rpy="0 0 0" />
			<mass
			  value="1.4711" />
			<inertia
			  ixx="0.0020528"
			  ixy="-4.2085E-07"
			  ixz="7.1213E-06"
			  iyy="0.0017982"
			  iyz="-5.7954E-06"
			  izz="0.0011948" />
		</inertial>
		<visual>
			<origin
			  xyz="0 0 0"
			  rpy="0 0 0" />
			<geometry>
				<mesh
				  filename="meshes/right_hip_roll_link.STL" />
			</geometry>
			<material
			  name="">
				<color
				  rgba="0.75294 0.75294 0.75294 1" />
			</material>
		</visual>
		<!-- <collision>
			<origin
			  xyz="0 0 0"
			  rpy="0 0 0" />
			<geometry>
				<mesh
				  filename="meshes/right_hip_roll_link.STL" />
			</geometry>
		</collision> -->
	</link>
	<joint
	  name="right_hip_roll_joint"
	  type="revolute">
		<origin
		  xyz="0.0331118430306478 -0.0519845204764556 -0.0243891056337237"
		  rpy="0 0 0" />
		<parent
		  link="right_hip_pitch_link" />
		<child
		  link="right_hip_roll_link" />
		<axis
		  xyz="0.983751487188846 0 0.179535543705788" />
		<limit lower="-2.9671" upper="0.5236" effort="139" velocity="20"/>
		<dynamics
		  damping="0.001"
		  friction="0.1" />
	</joint>
	<link
	  name="right_hip_yaw_link">
		<inertial>
			<origin
			  xyz="-0.0028381 0.0080695 -0.16937"
			  rpy="0 0 0" />
			<mass
			  value="1.7026" />
			<inertia
			  ixx="0.0016048"
			  ixy="-1.3381E-05"
			  ixz="-4.2382E-05"
			  iyy="0.0018182"
			  iyz="2.3829E-05"
			  izz="0.00117" />
		</inertial>
		<visual>
			<origin
			  xyz="0 0 0"
			  rpy="0 0 0" />
			<geometry>
				<mesh
				  filename="meshes/right_hip_yaw_link.STL" />
			</geometry>
			<material
			  name="">
				<color
				  rgba="0.75294 0.75294 0.75294 1" />
			</material>
		</visual>
		<collision>
			<origin
			  xyz="0 0 0"
			  rpy="0 0 0" />
			<geometry>
				<mesh
				  filename="meshes/right_hip_yaw_link.STL" />
			</geometry>
		</collision>
	</link>
	<joint
	  name="right_hip_yaw_joint"
	  type="revolute">
		<origin
		  xyz="-0.01311907566672 -0.00161737869551998 -0.16064396662623"
		  rpy="0 0 0" />
		<parent
		  link="right_hip_roll_link" />
		<child
		  link="right_hip_yaw_link" />
		<axis
		  xyz="-0.179524919152183 0.0108789930130303 0.983693270747759" />
		<limit
		  lower="-2.7576"
		  upper="2.7576"
		  effort="88"
		  velocity="32" />
		<dynamics
		  damping="0.001"
		  friction="0.1" />
	</joint>
	<link
	  name="right_knee_link">
		<inertial>
			<origin
			  xyz="0.0054963 0.013713 -0.16049"
			  rpy="0 0 0" />
			<mass
			  value="2.1904" />
			<inertia
			  ixx="0.0096748"
			  ixy="-5.2818E-06"
			  ixz="-5.3164E-05"
			  iyy="0.0098856"
			  iyz="-5.8029E-05"
			  izz="0.0012618" />
		</inertial>
		<visual>
			<origin
			  xyz="0 0 0"
			  rpy="0 0 0" />
			<geometry>
				<mesh
				  filename="meshes/right_knee_link.STL" />
			</geometry>
			<material
			  name="">
				<color
				  rgba="0.75294 0.75294 0.75294 1" />
			</material>
		</visual>
		<collision>
			<origin
			  xyz="0 0 0"
			  rpy="0 0 0" />
			<geometry>
				<mesh
				  filename="meshes/right_knee_link.STL" />
			</geometry>
		</collision>
	</link>
	<joint
	  name="right_knee_joint"
	  type="revolute">
		<origin
		  xyz="-0.00557954825104146 -0.0195970600960823 -0.210952119016347"
		  rpy="0 0 0" />
		<parent
		  link="right_hip_yaw_link" />
		<child
		  link="right_knee_link" />
		<axis
		  xyz="0.00411462509433713 0.999934458903443 -0.0106839954049106" />
		<limit
		  lower="-0.0873"
		  upper="2.8798"
		  effort="139"
		  velocity="20" />
		<dynamics
		  damping="0.001"
		  friction="0.1" />
	</joint>
	<link
	  name="right_ankle_pitch_link">
		<inertial>
			<origin
			  xyz="-0.0063925 -8.882E-05 -0.010823"
			  rpy="0 0 0" />
			<mass
			  value="0.0268" />
			<inertia
			  ixx="3.1501E-06"
			  ixy="4.9236E-09"
			  ixz="-9.9472E-07"
			  iyy="6.8796E-06"
			  iyz="-2.1822E-08"
			  izz="4.4456E-06" />
		</inertial>
		<visual>
			<origin
			  xyz="0 0 0"
			  rpy="0 0 0" />
			<geometry>
				<mesh
				  filename="meshes/right_ankle_pitch_link.STL" />
			</geometry>
			<material
			  name="">
				<color
				  rgba="0.59216 0.61961 0.65098 1" />
			</material>
		</visual>
		<!-- <collision>
			<origin
			  xyz="0 0 0"
			  rpy="0 0 0" />
			<geometry>
				<mesh
				  filename="meshes/right_ankle_pitch_link.STL" />
			</geometry>
		</collision> -->
	</link>
	<joint
	  name="right_ankle_pitch_joint"
	  type="revolute">
		<origin
		  xyz="0.000298418160850451 0.0114800766431144 -0.345309203051201"
		  rpy="0 0 0" />
		<parent
		  link="right_knee_link" />
		<child
		  link="right_ankle_pitch_link" />
		<axis
		  xyz="0.00416437182944981 0.999934453476817 -0.0106652124819988" />
		<limit
		  lower="-0.8727"
		  upper="0.5236"
		  effort="50"
		  velocity="37" />
		<dynamics
		  damping="0.001"
		  friction="0.1" />
	</joint>
	<link
	  name="right_ankle_roll_link">
		<inertial>
			<origin
			  xyz="0.074271 -0.0015944 -0.022784"
			  rpy="0 0 0" />
			<mass
			  value="0.66157" />
			<inertia
			  ixx="0.00033174"
			  ixy="-1.5628E-06"
			  ixz="3.6557E-05"
			  iyy="0.0023489"
			  iyz="-3.8178E-06"
			  izz="0.0025676" />
		</inertial>
		<visual>
			<origin
			  xyz="0 0 0"
			  rpy="0 0 0" />
			<geometry>
				<mesh
				  filename="meshes/right_ankle_roll_link.STL" />
			</geometry>
			<material
			  name="">
				<color
				  rgba="0.75294 0.75294 0.75294 1" />
			</material>
		</visual>
	<collision>
      <origin xyz="-0.026 -0.02 -0.04" rpy="0 0 0"/>
      <geometry>
        <sphere radius="0.005"/>
      </geometry>
    </collision>
    <collision>
      <origin xyz="-0.026 0.025 -0.04" rpy="0 0 0"/>
      <geometry>
        <sphere radius="0.005"/>
      </geometry>
    </collision>
    <collision>
      <origin xyz="0.19 -0.02 -0.04" rpy="0 0 0"/>
      <geometry>
        <sphere radius="0.005"/>
      </geometry>
    </collision>
    <collision>
      <origin xyz="0.19 0.03 -0.04" rpy="0 0 0"/>
      <geometry>
        <sphere radius="0.005"/>
      </geometry>
    </collision>
		<!-- <collision>
			<origin
			  xyz="0 0 0"
			  rpy="0 0 0" />
			<geometry>
				<mesh
				  filename="meshes/right_ankle_roll_link.STL" />
			</geometry>
		</collision> -->
	</link>
	<joint
	  name="right_ankle_roll_joint"
	  type="revolute">
		<origin
		  xyz="-0.0267497735970306 -8.05847676524363E-05 -0.0180001560716241"
		  rpy="0 0 0" />
		<parent
		  link="right_ankle_pitch_link" />
		<child
		  link="right_ankle_roll_link" />
		<axis
		  xyz="0.999991328965992 -0.00416413826354239 4.4106133148408E-05" />
		<limit
		  lower="-0.2618"
		  upper="0.2618"
		  effort="50"
		  velocity="37" />
		<dynamics
		  damping="0.001"
		  friction="0.1" />
	</joint>

	<!-- Torso -->
	<joint
	  name="waist_yaw_joint"
	  type="revolute">
		<origin
		  xyz="0 0.0645 0.1052"
		  rpy="0 0 0" />
		<parent
		  link="pelvis" />
		<child
		  link="torso_link" />
		<axis
		  xyz="0 0 1" />
		<limit
		  lower="-2.618"
		  upper="2.618"
		  effort="88"
		  velocity="32" />
		<dynamics
		  damping="0.001"
		  friction="0.1" />
	</joint>
	<link
  name="torso_link">
		<inertial>
			<origin
			  xyz="0.00532868910462625 0.000285167861888419 0.293644548467323"
			  rpy="0 0 0" />
			<mass
			  value="11.1695237784583" />
			<inertia
			  ixx="0.258504439366291"
			  ixy="5.80779181463182E-05"
			  ixz="-0.00108273477354124"
			  iyy="0.203058373480465"
			  iyz="0.000515277160703047"
			  izz="0.0913710853078841" />
		</inertial>
		<visual>
			<origin
			  xyz="0 0 0"
			  rpy="0 0 0" />
			<geometry>
				<mesh
				  filename="meshes/torso_link.STL" />
			</geometry>
			<material
			  name="">
				<color
				  rgba="0.752941176470588 0.752941176470588 0.752941176470588 1" />
			</material>
		</visual>
		<collision>
			<origin
			  xyz="0 0 0"
			  rpy="0 0 0" />
			<geometry>
				<mesh
				  filename="meshes/torso_link.STL" />
			</geometry>
		</collision>
	</link>


	<!-- IMU -->
	<link name="imu_in_torso"></link>
	<joint name="imu_in_torso_joint" type="fixed">
		<origin xyz="0 0 0.4185" rpy="0 0 0"/>
		<parent link="torso_link"/>
		<child link="imu_in_torso"/>
	</joint>

	<link name="imu_in_pelvis"></link>
	<joint name="imu_in_pelvis_joint" type="fixed">
		<origin xyz="0.04525 0 -0.08339" rpy="0 0 0"/>
		<parent link="pelvis"/>
		<child link="imu_in_pelvis"/>
	</joint>

	<!-- d435 -->
	<link name="d435_link"></link>
	<joint name="d435_joint" type="fixed">
		<origin xyz="0.0576235 0.01753 0.41987" rpy="0 0.8307767239493009 0"/>
		<parent link="torso_link"/>
		<child link="d435_link"/>
	</joint>

	<!-- mid360 -->
	<link name="mid360_link"></link>
	<joint name="mid360_joint" type="fixed">
		<origin xyz="0.0002835 0.00003 0.40618" rpy="0 0.04014257279586953 0"/>
		<parent link="torso_link"/>
		<child link="mid360_link"/>
	</joint>

	<!-- Arm -->
  <link
    name="left_shoulder_pitch_link">
    <inertial>
      <origin
        xyz="-2.06278318820923E-05 0.0380053096260141 -0.00426859991151743"
        rpy="0 0 0" />
      <mass
        value="0.856999833939288" />
      <inertia
        ixx="0.000473296384546546"
        ixy="-1.73151288748509E-07"
        ixz="2.59814251383628E-07"
        iyy="0.000497325398968742"
        iyz="3.18394942915739E-05"
        izz="0.000498183904349728" />
    </inertial>
    <visual>
      <origin
        xyz="0 0 0"
        rpy="0 0 0" />
      <geometry>
        <mesh
          filename="meshes/left_shoulder_pitch_link.STL" />
      </geometry>
      <material
        name="">
        <color
          rgba="0.752941176470588 0.752941176470588 0.752941176470588 1" />
      </material>
    </visual>
    <!-- <collision>
      <origin
        xyz="0 0 0"
        rpy="0 0 0" />
      <geometry>
        <mesh
          filename="meshes/left_shoulder_pitch_link.STL" />
      </geometry>
    </collision> -->
  </link>
  <joint
    name="left_shoulder_pitch_joint"
    type="revolute">
    <origin
      xyz="0.0060351 0.15795 0.37869"
      rpy="0 0 0" />
    <parent
      link="torso_link" />
    <child
      link="left_shoulder_pitch_link" />
    <axis
      xyz="0 0.9808 0.19502" />
    <limit
      lower="-3.0892"
      upper="2.6704"
      effort="25"
      velocity="37" />
    <dynamics
      damping="0.001"
      friction="0.1" />
  </joint>
  <link
    name="left_shoulder_roll_link">
    <inertial>
      <origin
        xyz="-0.0304908497181455 0.00612925501918749 -0.0649543186362219"
        rpy="0 0 0" />
      <mass
        value="0.576808851401746" />
      <inertia
        ixx="0.000288527363283887"
        ixy="3.46282487857729E-08"
        ixz="-3.71702018913451E-07"
        iyy="0.000352684303701337"
        iyz="7.47484015779909E-06"
        izz="0.000260107254778081" />
    </inertial>
    <visual>
      <origin
        xyz="0 0 0"
        rpy="0 0 0" />
      <geometry>
        <mesh
          filename="meshes/left_shoulder_roll_link.STL" />
      </geometry>
      <material
        name="">
        <color
          rgba="0.752941176470588 0.752941176470588 0.752941176470588 1" />
      </material>
    </visual>
    <collision>
      <origin
        xyz="0 0 0"
        rpy="0 0 0" />
      <geometry>
        <mesh
          filename="meshes/left_shoulder_roll_link.STL" />
      </geometry>
    </collision>
  </link>
  <joint
    name="left_shoulder_roll_joint"
    type="revolute">
    <origin
      xyz="0.0302226899164981 0.0399730578485864 -0.00618298307795967"
      rpy="0 0 0" />
    <parent
      link="left_shoulder_pitch_link" />
    <child
      link="left_shoulder_roll_link" />
    <axis
      xyz="0.999999541179562 0.00018681462330965 -0.000939542953616698" />
    <limit
      lower="-1.5882"
      upper="2.2515"
      effort="25"
      velocity="37" />
    <dynamics
      damping="0.001"
      friction="0.1" />
  </joint>
  <link
    name="left_shoulder_yaw_link">
    <inertial>
      <origin
        xyz="0.00973446713483218 -0.00355452917304089 -0.0984344334051088"
        rpy="0 0 0" />
      <mass
        value="0.787455808914453" />
      <inertia
        ixx="0.000798734244449371"
        ixy="1.30476414433409E-05"
        ixz="4.56600808937558E-05"
        iyy="0.000801142107585112"
        iyz="-5.2769245019718E-05"
        izz="0.000411674161293424" />
    </inertial>
    <visual>
      <origin
        xyz="0 0 0"
        rpy="0 0 0" />
      <geometry>
        <mesh
          filename="meshes/left_shoulder_yaw_link.STL" />
      </geometry>
      <material
        name="">
        <color
          rgba="0.752941176470588 0.752941176470588 0.752941176470588 1" />
      </material>
    </visual>
    <!-- <collision>
      <origin
        xyz="0 0 0"
        rpy="0 0 0" />
      <geometry>
        <mesh
          filename="meshes/left_shoulder_yaw_link.STL" />
      </geometry>
    </collision> -->
  </link>
  <joint
    name="left_shoulder_yaw_joint"
    type="revolute">
    <origin
      xyz="-0.0305739738195319 0.00666160658504897 -0.0743466956069563"
      rpy="0 0 0" />
    <parent
      link="left_shoulder_roll_link" />
    <child
      link="left_shoulder_yaw_link" />
    <axis
      xyz="0.00431492897565982 -0.00574316917972918 0.999974198364992" />
    <limit
      lower="-2.618"
      upper="2.618"
      effort="25"
      velocity="37" />
    <dynamics
      damping="0.001"
      friction="0.1" />
  </joint>
  <link
    name="left_elbow_link">
    <inertial>
      <origin
        xyz="0.0674633164459992 -0.0146400565291789 -0.0089513623057359"
        rpy="0 0 0" />
      <mass
        value="0.793513817454599" />
      <inertia
        ixx="0.000338426284508813"
        ixy="1.40767122465403E-05"
        ixz="9.47794373527156E-06"
        iyy="0.000426529749382101"
        iyz="-2.20455807300815E-06"
        izz="0.000413430286177196" />
    </inertial>
    <visual>
      <origin
        xyz="0 0 0"
        rpy="0 0 0" />
      <geometry>
        <mesh
          filename="meshes/left_elbow_link.STL" />
      </geometry>
      <material
        name="">
        <color
          rgba="0.752941176470588 0.752941176470588 0.752941176470588 1" />
      </material>
    </visual>
    <collision>
      <origin
        xyz="0 0 0"
        rpy="0 0 0" />
      <geometry>
        <mesh
          filename="meshes/left_elbow_link.STL" />
      </geometry>
    </collision>
  </link>
  <joint
    name="left_elbow_joint"
    type="revolute">
    <origin
      xyz="0.0147830895658755 0.0215096305520125 -0.113822056389066"
      rpy="0 0 0" />
    <parent
      link="left_shoulder_yaw_link" />
    <child
      link="left_elbow_link" />
    <axis
      xyz="-0.0244434384745122 0.999684111752619 0.00584765123111828" />
    <limit
      lower="-1.0472"
      upper="2.0944"
      effort="25"
      velocity="37" />
    <dynamics
      damping="0.001"
      friction="0.1" />
  </joint>
  <link
    name="left_wrist_roll_rubber_hand">
    <inertial>
      <origin
        xyz="0.139725886449084 0.0033661823762148 0.00407283030239641"
        rpy="0 0 0" />
      <mass
        value="0.278928121537221" />
      <inertia
        ixx="0.000166546170613997"
        ixy="3.22856586018748E-05"
        ixz="-3.58051997518384E-06"
        iyy="0.00045103937757739"
        iyz="4.12219767130447E-06"
        izz="0.000373732169646882" />
    </inertial>
    <visual>
      <origin
        xyz="0 0 0"
        rpy="0 0 0" />
      <geometry>
        <mesh
          filename="meshes/left_wrist_roll_rubber_hand.STL" />
      </geometry>
      <material
        name="">
        <color
          rgba="0.752941176470588 0.752941176470588 0.752941176470588 1" />
      </material>
    </visual>
    <collision>
      <origin
        xyz="0 0 0"
        rpy="0 0 0" />
      <geometry>
        <mesh
          filename="meshes/left_wrist_roll_rubber_hand.STL" />
      </geometry>
    </collision>
  </link>
  <joint
    name="left_wrist_roll_joint"
    type="revolute">
    <origin
      xyz="0.10094 -0.01566 -0.0088683"
      rpy="0 0 0" />
    <parent
      link="left_elbow_link" />
    <child
      link="left_wrist_roll_rubber_hand" />
    <axis
      xyz="0.99964 0.024374 0.01149" />
    <limit
      lower="-1.9722"
      upper="1.9722"
      effort="25"
      velocity="37" />
    <dynamics
      damping="0.001"
      friction="0.1" />
  </joint>
  <link
    name="right_shoulder_pitch_link">
    <inertial>
      <origin
        xyz="-4.06186256698077E-05 -0.0380052994359525 -0.00426854825462361"
        rpy="0 0 0" />
      <mass
        value="0.856999831581854" />
      <inertia
        ixx="0.000473293689361305"
        ixy="-3.13303387142504E-07"
        ixz="-1.63689093500112E-07"
        iyy="0.000497325880842342"
        iyz="-3.1838016215121E-05"
        izz="0.000498186077635359" />
    </inertial>
    <visual>
      <origin
        xyz="0 0 0"
        rpy="0 0 0" />
      <geometry>
        <mesh
          filename="meshes/right_shoulder_pitch_link.STL" />
      </geometry>
      <material
        name="">
        <color
          rgba="0.752941176470588 0.752941176470588 0.752941176470588 1" />
      </material>
    </visual>
    <!-- <collision>
      <origin
        xyz="0 0 0"
        rpy="0 0 0" />
      <geometry>
        <mesh
          filename="meshes/right_shoulder_pitch_link.STL" />
      </geometry>
    </collision> -->
  </link>
  <joint
    name="right_shoulder_pitch_joint"
    type="revolute">
    <origin
      xyz="0.0060355 -0.15795 0.37869"
      rpy="0 0 0" />
    <parent
      link="torso_link" />
    <child
      link="right_shoulder_pitch_link" />
    <axis
      xyz="0 0.9808 -0.19502" />
    <limit
      lower="-3.0892"
      upper="2.6704"
      effort="25"
      velocity="37" />
    <dynamics
      damping="0.001"
      friction="0.1" />
  </joint>
  <link
    name="right_shoulder_roll_link">
    <inertial>
      <origin
        xyz="-0.0304858385982802 -0.00416588748338423 -0.0653459178909587"
        rpy="0 0 0" />
      <mass
        value="0.576808847938166" />
      <inertia
        ixx="0.000288527475375692"
        ixy="-3.49958512838216E-08"
        ixz="-3.6958736552977E-07"
        iyy="0.00035268434880898"
        iyz="-7.47484231580634E-06"
        izz="0.000260107184085235" />
    </inertial>
    <visual>
      <origin
        xyz="0 0 0"
        rpy="0 0 0" />
      <geometry>
        <mesh
          filename="meshes/right_shoulder_roll_link.STL" />
      </geometry>
      <material
        name="">
        <color
          rgba="0.752941176470588 0.752941176470588 0.752941176470588 1" />
      </material>
    </visual>
    <collision>
      <origin
        xyz="0 0 0"
        rpy="0 0 0" />
      <geometry>
        <mesh
          filename="meshes/right_shoulder_roll_link.STL" />
      </geometry>
    </collision>
  </link>
  <joint
    name="right_shoulder_roll_joint"
    type="revolute">
    <origin
      xyz="0.0302233370301298 -0.0419364289067457 -0.00579140745188228"
      rpy="0 0 0" />
    <parent
      link="right_shoulder_pitch_link" />
    <child
      link="right_shoulder_roll_link" />
    <axis
      xyz="0.999999607385452 -0.000172811520734623 -0.000869117437031054" />
    <limit
      lower="-2.2515"
      upper="1.5882"
      effort="25"
      velocity="37" />
    <dynamics
      damping="0.001"
      friction="0.1" />
  </joint>
  <link
    name="right_shoulder_yaw_link">
    <inertial>
      <origin
        xyz="0.00974134532542396 0.00355465648017247 -0.0984337348434889"
        rpy="0 0 0" />
      <mass
        value="0.78745626155838" />
      <inertia
        ixx="0.000798728522415332"
        ixy="-1.30513992177155E-05"
        ixz="4.56866039791013E-05"
        iyy="0.000801141900766942"
        iyz="5.27688311348563E-05"
        izz="0.000411680791149739" />
    </inertial>
    <visual>
      <origin
        xyz="0 0 0"
        rpy="0 0 0" />
      <geometry>
        <mesh
          filename="meshes/right_shoulder_yaw_link.STL" />
      </geometry>
      <material
        name="">
        <color
          rgba="0.752941176470588 0.752941176470588 0.752941176470588 1" />
      </material>
    </visual>
    <!-- <collision>
      <origin
        xyz="0 0 0"
        rpy="0 0 0" />
      <geometry>
        <mesh
          filename="meshes/right_shoulder_yaw_link.STL" />
      </geometry>
    </collision> -->
  </link>
  <joint
    name="right_shoulder_yaw_joint"
    type="revolute">
    <origin
      xyz="-0.0305682965552232 -0.00469824040191841 -0.0747382957496521"
      rpy="0 0 0" />
    <parent
      link="right_shoulder_roll_link" />
    <child
      link="right_shoulder_yaw_link" />
    <axis
      xyz="0.00424442481293312 0.0057432291085079 0.999974499763576" />
    <limit
      lower="-2.618"
      upper="2.618"
      effort="25"
      velocity="37" />
    <dynamics
      damping="0.001"
      friction="0.1" />
  </joint>
  <link
    name="right_elbow_link">
    <inertial>
      <origin
        xyz="0.0675187826593757 0.0151122155899943 -0.00926345117580889"
        rpy="0 0 0" />
      <mass
        value="0.793513831410031" />
      <inertia
        ixx="0.00033945220125228"
        ixy="-1.60929853366593E-05"
        ixz="1.05883756942239E-05"
        iyy="0.000425819042673737"
        iyz="2.67957411058312E-06"
        izz="0.000413115064491519" />
    </inertial>
    <visual>
      <origin
        xyz="0 0 0"
        rpy="0 0 0" />
      <geometry>
        <mesh
          filename="meshes/right_elbow_link.STL" />
      </geometry>
      <material
        name="">
        <color
          rgba="0.752941176470588 0.752941176470588 0.752941176470588 1" />
      </material>
    </visual>
    <collision>
      <origin
        xyz="0 0 0"
        rpy="0 0 0" />
      <geometry>
        <mesh
          filename="meshes/right_elbow_link.STL" />
      </geometry>
    </collision>
  </link>
  <joint
    name="right_elbow_joint"
    type="revolute">
    <origin
      xyz="0.0147914067099791 -0.0215094234845738 -0.113821014989034"
      rpy="0 0 0" />
    <parent
      link="right_shoulder_yaw_link" />
    <child
      link="right_elbow_link" />
    <axis
      xyz="0.024429851550431 0.999684453941611 -0.00584593026703749" />
    <limit
      lower="-1.0472"
      upper="2.0944"
      effort="25"
      velocity="37" />
    <dynamics
      damping="0.001"
      friction="0.1" />
  </joint>
  <link
    name="right_wrist_roll_rubber_hand">
    <inertial>
      <origin
        xyz="0.139710047442782 -0.00462270140566992 0.00492851158423267"
        rpy="0 0 0" />
      <mass
        value="0.278919926883193" />
      <inertia
        ixx="0.00016654394479864"
        ixy="-3.22919649250768E-05"
        ixz="-3.59062693772289E-06"
        iyy="0.00045102641091086"
        iyz="-4.12526205313047E-06"
        izz="0.000373718224044052" />
    </inertial>
    <visual>
      <origin
        xyz="0 0 0"
        rpy="0 0 0" />
      <geometry>
        <mesh
          filename="meshes/right_wrist_roll_rubber_hand.STL" />
      </geometry>
      <material
        name="">
        <color
          rgba="0.752941176470588 0.752941176470588 0.752941176470588 1" />
      </material>
    </visual>
    <collision>
      <origin
        xyz="0 0 0"
        rpy="0 0 0" />
      <geometry>
        <mesh
          filename="meshes/right_wrist_roll_rubber_hand.STL" />
      </geometry>
    </collision>
  </link>
  <joint
    name="right_wrist_roll_joint"
    type="revolute">
    <origin
      xyz="0.100956192797708 0.0169198167231833 -0.00970650339272482"
      rpy="0 0 0" />
    <parent
      link="right_elbow_link" />
    <child
      link="right_wrist_roll_rubber_hand" />
    <axis
      xyz="0.999990657313489 -0.000842993866582275 -0.00423965176381057" />
    <limit
      lower="-1.9722"
      upper="1.9722"
      effort="25"
      velocity="37" />
    <dynamics
      damping="0.001"
      friction="0.1" />
  </joint>
</robot>