<mujoco model="arcus_1.5_3">
  <compiler angle="radian" meshdir="meshes/"/>

  <statistic meansize="0.144785" extent="1.23314" center="0.025392 2.0634e-05 -2.245975"/>
   <default>
    <joint damping="0.01" armature="0.01" frictionloss="0.1"/>
  </default>

  <asset>
    <mesh name="pelvis" file="pelvis.STL"/>
    <mesh name="torso_link" file="torso_link.STL"/>
    <mesh name="left_shoulder_pitch_link" file="left_shoulder_pitch_link.STL"/>
    <mesh name="left_shoulder_roll_link" file="left_shoulder_roll_link.STL"/>
    <mesh name="left_shoulder_yaw_link" file="left_shoulder_yaw_link.STL"/>
    <mesh name="left_elbow_link" file="left_elbow_link.STL"/>
    <mesh name="left_wrist_roll_rubber_hand" file="left_wrist_roll_rubber_hand.STL"/>
    <mesh name="right_shoulder_pitch_link" file="right_shoulder_pitch_link.STL"/>
    <mesh name="right_shoulder_roll_link" file="right_shoulder_roll_link.STL"/>
    <mesh name="right_shoulder_yaw_link" file="right_shoulder_yaw_link.STL"/>
    <mesh name="right_elbow_link" file="right_elbow_link.STL"/>
    <mesh name="right_wrist_roll_rubber_hand" file="right_wrist_roll_rubber_hand.STL"/>
    <mesh name="left_hip_pitch_link" file="left_hip_pitch_link.STL"/>
    <mesh name="left_hip_roll_link" file="left_hip_roll_link.STL"/>
    <mesh name="left_hip_yaw_link" file="left_hip_yaw_link.STL"/>
    <mesh name="left_knee_link" file="left_knee_link.STL"/>
    <mesh name="left_ankle_pitch_link" file="left_ankle_pitch_link.STL"/>
    <mesh name="left_ankle_roll_link" file="left_ankle_roll_link.STL"/>
    <mesh name="right_hip_pitch_link" file="right_hip_pitch_link.STL"/>
    <mesh name="right_hip_roll_link" file="right_hip_roll_link.STL"/>
    <mesh name="right_hip_yaw_link" file="right_hip_yaw_link.STL"/>
    <mesh name="right_knee_link" file="right_knee_link.STL"/>
    <mesh name="right_ankle_pitch_link" file="right_ankle_pitch_link.STL"/>
    <mesh name="right_ankle_roll_link" file="right_ankle_roll_link.STL"/>
  </asset>

  <worldbody>
    <body name="pelvis" pos="0 0 0.805">
      <site name="imu" size="0.01" pos="0.045 0.063 0.02"/>
      <inertial pos="-1.0044e-07 0.0645 0.02807" quat="1 -6.1259e-06 2.53595e-06 3.9569e-06" mass="4.806" diaginertia="0.012426 0.0099675 0.0086797"/>
      <joint name="floating_base_joint" type="free" limited="false" actuatorfrclimited="false"/>
      <geom type="mesh" contype="0" conaffinity="0" group="1" density="0" rgba="0.75294 0.75294 0.75294 1" mesh="pelvis"/>
      <geom type="mesh" rgba="0.75294 0.75294 0.75294 1" mesh="pelvis"/>
      <body name="left_hip_pitch_link" pos="0 0.129 0">
        <inertial pos="0.00503146 0.0509318 -0.0289375" quat="0.996356 0.0347664 -0.0762266 -0.0159687" mass="1.39231" diaginertia="0.00120611 0.00108551 0.000845183"/>
        <joint name="left_hip_pitch_joint" pos="0 0 0" axis="0 1 0" range="-2.5307 2.8798" actuatorfrcrange="-88 88" damping="0.01" frictionloss="0.1"/>
        <geom type="mesh" contype="0" conaffinity="0" group="1" density="0" rgba="0.752941 0.752941 0.752941 1" mesh="left_hip_pitch_link"/>
        <body name="left_hip_roll_link" pos="0.033112 0.051985 -0.024389">
          <inertial pos="-0.0146816 -0.00128508 -0.116823" quat="0.999973 -0.00591336 -0.00415001 -0.000974222" mass="1.47113" diaginertia="0.00205288 0.00179822 0.00119466"/>
          <joint name="left_hip_roll_joint" pos="0 0 0" axis="0.983751 0 0.17954" range="-0.5236 2.9671" actuatorfrcrange="-139 139" damping="0.01" frictionloss="0.1"/>
          <geom type="mesh" contype="0" conaffinity="0" group="1" density="0" rgba="0.752941 0.752941 0.752941 1" mesh="left_hip_roll_link"/>
          <geom type="mesh" rgba="0.752941 0.752941 0.752941 1" mesh="left_hip_roll_link"/>
          <body name="left_hip_yaw_link" pos="-0.013119 -0.0017733 -0.16064">
            <inertial pos="-0.00287598 -0.0116858 -0.169154" quat="0.732678 0.0120048 0.0537269 0.678345" mass="1.7026" diaginertia="0.0018201 0.00160778 0.0011651"/>
            <joint name="left_hip_yaw_joint" pos="0 0 0" axis="-0.179521 0.0109 0.983694" range="-2.7576 2.7576" actuatorfrcrange="-88 88" damping="0.01" frictionloss="0.1"/>
            <geom type="mesh" contype="0" conaffinity="0" group="1" density="0" rgba="0.752941 0.752941 0.752941 1" mesh="left_hip_yaw_link"/>
            <body name="left_knee_link" pos="-0.0055115 0.015094 -0.21132">
              <inertial pos="0.00617211 -0.0174236 -0.159954" quat="0.71736 -0.00499988 0.00537075 0.696664" mass="2.19048" diaginertia="0.00988759 0.0096765 0.00126109"/>
              <joint name="left_knee_joint" pos="0 0 0" axis="0.0019798 0.999941 -0.010723" range="-0.0873 2.8798" actuatorfrcrange="-139 139" damping="0.01" frictionloss="0.1"/>
              <geom type="mesh" contype="0" conaffinity="0" group="1" density="0" rgba="0.752941 0.752941 0.752941 1" mesh="left_knee_link"/>
              <geom type="mesh" rgba="0.752941 0.752941 0.752941 1" mesh="left_knee_link"/>
              <body name="left_ankle_pitch_link" pos="0.0020129 -0.019118 -0.34482">
                <inertial pos="-0.00639266 -0.000103937 -0.010823" quat="0.610098 0.358812 0.364641 0.605039" mass="0.0267996" diaginertia="6.87989e-06 4.98464e-06 2.61081e-06"/>
                <joint name="left_ankle_pitch_joint" pos="0 0 0" axis="0.0019299 0.99994 -0.010742" range="-0.8727 0.5236" actuatorfrcrange="-50 50" damping="0.01" frictionloss="0.1"/>
                <geom type="mesh" contype="0" conaffinity="0" group="1" density="0" rgba="0.592157 0.619608 0.65098 1" mesh="left_ankle_pitch_link"/>
                <body name="left_ankle_roll_link" pos="-0.02675 -0.00014174 -0.017999">
                  <inertial pos="0.0742707 0.00114673 -0.0227875" quat="0.00845167 0.712853 0.00382758 0.701252" mass="0.661703" diaginertia="0.00256889 0.00234942 0.000331169"/>
                  <joint name="left_ankle_roll_joint" pos="0 0 0" axis="0.999998 -0.0019299 0" range="-0.2618 0.2618" actuatorfrcrange="-50 50" damping="0.01" frictionloss="0.1"/>
                  <geom type="mesh" contype="0" conaffinity="0" group="1" density="0" rgba="0.752941 0.752941 0.752941 1" mesh="left_ankle_roll_link"/>
                  <geom size="0.005" pos="-0.026 0.02 -0.04" rgba="0.752941 0.752941 0.752941 1"/>
                  <geom size="0.005" pos="-0.026 -0.025 -0.04" rgba="0.752941 0.752941 0.752941 1"/>
                  <geom size="0.005" pos="0.19 0.02 -0.04" rgba="0.752941 0.752941 0.752941 1"/>
                  <geom size="0.005" pos="0.19 -0.03 -0.04" rgba="0.752941 0.752941 0.752941 1"/>
                </body>
              </body>
            </body>
          </body>
        </body>
      </body>
      <body name="right_hip_pitch_link">
        <inertial pos="0.00503145 -0.0509318 -0.0289375" quat="0.996356 -0.0347663 -0.0762271 0.0159679" mass="1.39231" diaginertia="0.00120611 0.00108551 0.000845184"/>
        <joint name="right_hip_pitch_joint" pos="0 0 0" axis="0 1 0" range="-2.5307 2.8798" actuatorfrcrange="-88 88" damping="0.01" frictionloss="0.1"/>
        <geom type="mesh" contype="0" conaffinity="0" group="1" density="0" rgba="0.752941 0.752941 0.752941 1" mesh="right_hip_pitch_link"/>
        <body name="right_hip_roll_link" pos="0.033112 -0.051985 -0.024389">
          <inertial pos="-0.0146813 -0.00116059 -0.116824" quat="0.999979 -0.00479434 -0.00415106 -0.000940557" mass="1.47114" diaginertia="0.00205289 0.00179822 0.00119466"/>
          <joint name="right_hip_roll_joint" pos="0 0 0" axis="0.983751 0 0.17954" range="-2.9671 0.5236" actuatorfrcrange="-139 139" damping="0.01" frictionloss="0.1"/>
          <geom type="mesh" contype="0" conaffinity="0" group="1" density="0" rgba="0.752941 0.752941 0.752941 1" mesh="right_hip_roll_link"/>
          <geom type="mesh" rgba="0.752941 0.752941 0.752941 1" mesh="right_hip_roll_link"/>
          <body name="right_hip_yaw_link" pos="-0.013119 -0.0016174 -0.16064">
            <inertial pos="-0.00283812 0.00806954 -0.169366" quat="0.680305 0.046479 0.0197499 0.731187" mass="1.7026" diaginertia="0.0018201 0.00160778 0.0011651"/>
            <joint name="right_hip_yaw_joint" pos="0 0 0" axis="-0.179521 0.010879 0.983694" range="-2.7576 2.7576" actuatorfrcrange="-88 88" damping="0.01" frictionloss="0.1"/>
            <geom type="mesh" contype="0" conaffinity="0" group="1" density="0" rgba="0.752941 0.752941 0.752941 1" mesh="right_hip_yaw_link"/>
            <body name="right_knee_link" pos="-0.0055795 -0.019597 -0.21095">
              <inertial pos="0.0054963 0.0137133 -0.160485" quat="0.698809 -9.09053e-05 0.00461676 0.715293" mass="2.1904" diaginertia="0.00988607 0.00967499 0.00126103"/>
              <joint name="right_knee_joint" pos="0 0 0" axis="0.00411462 0.999934 -0.010684" range="-0.0873 2.8798" actuatorfrcrange="-139 139" damping="0.01" frictionloss="0.1"/>
              <geom type="mesh" contype="0" conaffinity="0" group="1" density="0" rgba="0.752941 0.752941 0.752941 1" mesh="right_knee_link"/>
              <geom type="mesh" rgba="0.752941 0.752941 0.752941 1" mesh="right_knee_link"/>
              <body name="right_ankle_pitch_link" pos="0.00029842 0.01148 -0.34531">
                <inertial pos="-0.00639245 -8.88199e-05 -0.0108232" quat="0.610767 0.35923 0.364204 0.604378" mass="0.0267996" diaginertia="6.87989e-06 4.98464e-06 2.61081e-06"/>
                <joint name="right_ankle_pitch_joint" pos="0 0 0" axis="0.00416442 0.999934 -0.010665" range="-0.8727 0.5236" actuatorfrcrange="-50 50" damping="0.01" frictionloss="0.1"/>
                <geom type="mesh" contype="0" conaffinity="0" group="1" density="0" rgba="0.592157 0.619608 0.65098 1" mesh="right_ankle_pitch_link"/>
                <body name="right_ankle_roll_link" pos="-0.02675 -8.0585e-05 -0.018">
                  <inertial pos="0.0742718 -0.0015945 -0.0227843" quat="-0.00640506 0.712835 -0.00598115 0.701277" mass="0.661564" diaginertia="0.0025683 0.00234883 0.000331145"/>
                  <joint name="right_ankle_roll_joint" pos="0 0 0" axis="0.999991 -0.00416411 4.41061e-05" range="-0.2618 0.2618" actuatorfrcrange="-50 50" damping="0.01" frictionloss="0.1"/>
                  <geom type="mesh" contype="0" conaffinity="0" group="1" density="0" rgba="0.752941 0.752941 0.752941 1" mesh="right_ankle_roll_link"/>
                  <geom size="0.005" pos="-0.026 -0.02 -0.04" rgba="0.752941 0.752941 0.752941 1"/>
                  <geom size="0.005" pos="-0.026 0.025 -0.04" rgba="0.752941 0.752941 0.752941 1"/>
                  <geom size="0.005" pos="0.19 -0.02 -0.04" rgba="0.752941 0.752941 0.752941 1"/>
                  <geom size="0.005" pos="0.19 0.03 -0.04" rgba="0.752941 0.752941 0.752941 1"/>
                </body>
              </body>
            </body>
          </body>
        </body>
      </body>
      <body name="torso_link" pos="0 0.0645 0.1052">
        <site name="secondary_imu" size="0.01" pos="0 0 0.4185"/>
        <inertial pos="0.00532869 0.000285168 0.293645" quat="0.999992 0.00230979 0.00323856 0.000486097" mass="11.1695" diaginertia="0.258512 0.203061 0.0913617"/>
        <joint name="waist_yaw_joint" pos="0 0 0" axis="0 0 1" range="-2.618 2.618" actuatorfrcrange="-88 88" damping="0.01" frictionloss="0.1"/>
        <geom type="mesh" contype="0" conaffinity="0" group="1" density="0" rgba="0.752941 0.752941 0.752941 1" mesh="torso_link"/>
        <geom type="mesh" rgba="0.752941 0.752941 0.752941 1" mesh="torso_link"/>
        <body name="left_shoulder_pitch_link" pos="0.0060351 0.15795 0.37869">
          <inertial pos="-2.06278e-05 0.0380053 -0.0042686" quat="0.65823 0.259414 -0.286054 0.646228" mass="0.857" diaginertia="0.000529597 0.000473309 0.0004659"/>
          <joint name="left_shoulder_pitch_joint" pos="0 0 0" axis="0 0.980799 0.19502" range="-3.0892 2.6704" actuatorfrcrange="-25 25" damping="0.01" frictionloss="0.1"/>
          <geom type="mesh" contype="0" conaffinity="0" group="1" density="0" rgba="0.752941 0.752941 0.752941 1" mesh="left_shoulder_pitch_link"/>
          <body name="left_shoulder_roll_link" pos="0.030223 0.039973 -0.006183">
            <inertial pos="-0.0304908 0.00612926 -0.0649543" quat="0.70637 0.032838 -0.0237498 0.706682" mass="0.576809" diaginertia="0.000353284 0.000288532 0.000259503"/>
            <joint name="left_shoulder_roll_joint" pos="0 0 0" axis="1 0.00018681 -0.00093954" range="-1.5882 2.2515" actuatorfrcrange="-25 25" damping="0.01" frictionloss="0.1"/>
            <geom type="mesh" contype="0" conaffinity="0" group="1" density="0" rgba="0.752941 0.752941 0.752941 1" mesh="left_shoulder_roll_link"/>
            <geom type="mesh" rgba="0.752941 0.752941 0.752941 1" mesh="left_shoulder_roll_link"/>
            <body name="left_shoulder_yaw_link" pos="-0.030574 0.0066616 -0.074347">
              <inertial pos="0.00973447 -0.00355453 -0.0984344" quat="0.889891 -0.0859779 -0.0223963 0.447438" mass="0.787456" diaginertia="0.000813348 0.000799077 0.000399126"/>
              <joint name="left_shoulder_yaw_joint" pos="0 0 0" axis="0.00431492 -0.00574322 0.999974" range="-2.618 2.618" actuatorfrcrange="-25 25" damping="0.01" frictionloss="0.1"/>
              <geom type="mesh" contype="0" conaffinity="0" group="1" density="0" rgba="0.752941 0.752941 0.752941 1" mesh="left_shoulder_yaw_link"/>
              <body name="left_elbow_link" pos="0.014783 0.02151 -0.11382">
                <inertial pos="0.0674633 -0.0146401 -0.00895136" quat="0.513974 0.556913 0.501273 0.417618" mass="0.793514" diaginertia="0.00042876 0.000414596 0.000335031"/>
                <joint name="left_elbow_joint" pos="0 0 0" axis="-0.0244431 0.999684 0.00584772" range="-1.0472 2.0944" actuatorfrcrange="-25 25" damping="0.01" frictionloss="0.1"/>
                <geom type="mesh" contype="0" conaffinity="0" group="1" density="0" rgba="0.752941 0.752941 0.752941 1" mesh="left_elbow_link"/>
                <geom type="mesh" rgba="0.752941 0.752941 0.752941 1" mesh="left_elbow_link"/>
                <body name="left_wrist_roll_rubber_hand" pos="0.10094 -0.01566 -0.0088683">
                  <inertial pos="0.139726 0.00336618 0.00407283" quat="0.521175 0.532624 0.454737 0.487752" mass="0.278928" diaginertia="0.000454826 0.00037364 0.000162852"/>
                  <joint name="left_wrist_roll_joint" pos="0 0 0" axis="0.999637 0.0243739 0.01149" range="-1.9722 1.9722" actuatorfrcrange="-25 25" damping="0.01" frictionloss="0.1"/>
                  <geom type="mesh" contype="0" conaffinity="0" group="1" density="0" rgba="0.752941 0.752941 0.752941 1" mesh="left_wrist_roll_rubber_hand"/>
                  <geom type="mesh" rgba="0.752941 0.752941 0.752941 1" mesh="left_wrist_roll_rubber_hand"/>
                </body>
              </body>
            </body>
          </body>
        </body>
        <body name="right_shoulder_pitch_link" pos="0.0060355 -0.15795 0.37869">
          <inertial pos="-4.06186e-05 -0.0380053 -0.00426855" quat="0.287891 0.646559 -0.65782 0.257593" mass="0.857" diaginertia="0.000529597 0.000473309 0.0004659"/>
          <joint name="right_shoulder_pitch_joint" pos="0 0 0" axis="0 0.980799 -0.19502" range="-3.0892 2.6704" actuatorfrcrange="-25 25" damping="0.01" frictionloss="0.1"/>
          <geom type="mesh" contype="0" conaffinity="0" group="1" density="0" rgba="0.752941 0.752941 0.752941 1" mesh="right_shoulder_pitch_link"/>
          <body name="right_shoulder_roll_link" pos="0.030223 -0.041936 -0.0057914">
            <inertial pos="-0.0304858 -0.00416589 -0.0653459" quat="0.706678 -0.0237749 0.0328128 0.706374" mass="0.576809" diaginertia="0.000353284 0.000288532 0.000259503"/>
            <joint name="right_shoulder_roll_joint" pos="0 0 0" axis="1 -0.00017281 -0.00086912" range="-2.2515 1.5882" actuatorfrcrange="-25 25" damping="0.01" frictionloss="0.1"/>
            <geom type="mesh" contype="0" conaffinity="0" group="1" density="0" rgba="0.752941 0.752941 0.752941 1" mesh="right_shoulder_roll_link"/>
            <geom type="mesh" rgba="0.752941 0.752941 0.752941 1" mesh="right_shoulder_roll_link"/>
            <body name="right_shoulder_yaw_link" pos="-0.030568 -0.0046982 -0.074738">
              <inertial pos="0.00974135 0.00355466 -0.0984337" quat="0.447425 -0.0224274 -0.0859936 0.889895" mass="0.787456" diaginertia="0.000813348 0.000799077 0.000399126"/>
              <joint name="right_shoulder_yaw_joint" pos="0 0 0" axis="0.00424442 0.00574323 0.999974" range="-2.618 2.618" actuatorfrcrange="-25 25" damping="0.01" frictionloss="0.1"/>
              <geom type="mesh" contype="0" conaffinity="0" group="1" density="0" rgba="0.752941 0.752941 0.752941 1" mesh="right_shoulder_yaw_link"/>
              <body name="right_elbow_link" pos="0.014791 -0.021509 -0.11382">
                <inertial pos="0.0675188 0.0151122 -0.00926345" quat="0.40712 0.498736 0.56601 0.514925" mass="0.793514" diaginertia="0.00042876 0.000414595 0.000335031"/>
                <joint name="right_elbow_joint" pos="0 0 0" axis="0.0244301 0.999684 -0.00584593" range="-1.0472 2.0944" actuatorfrcrange="-25 25" damping="0.01" frictionloss="0.1"/>
                <geom type="mesh" contype="0" conaffinity="0" group="1" density="0" rgba="0.752941 0.752941 0.752941 1" mesh="right_elbow_link"/>
                <geom type="mesh" rgba="0.752941 0.752941 0.752941 1" mesh="right_elbow_link"/>
                <body name="right_wrist_roll_rubber_hand" pos="0.10096 0.01692 -0.0097065">
                  <inertial pos="0.13971 -0.0046227 0.00492851" quat="0.487763 0.454713 0.532621 0.521189" mass="0.27892" diaginertia="0.000454815 0.000373626 0.000162848"/>
                  <joint name="right_wrist_roll_joint" pos="0 0 0" axis="0.999991 -0.000842991 -0.0042397" range="-1.9722 1.9722" actuatorfrcrange="-25 25" damping="0.01" frictionloss="0.1"/>
                  <geom type="mesh" contype="0" conaffinity="0" group="1" density="0" rgba="0.752941 0.752941 0.752941 1" mesh="right_wrist_roll_rubber_hand"/>
                  <geom type="mesh" rgba="0.752941 0.752941 0.752941 1" mesh="right_wrist_roll_rubber_hand"/>
                </body>
              </body>
            </body>
          </body>
        </body>
      </body>
    </body>

    <body name="waist_roll" pos="0 0 20">
      <inertial pos="0.0 0.0 0.0" mass="1e-03"
        diaginertia="1e-03 1e-03 1e-03" />
      <joint name="waist_roll_joint" />
    </body>
    <body name="waist_pitch" pos="0 0 20">
      <inertial pos="0.0 0.0 0.0" mass="1e-03"
        diaginertia="1e-03 1e-03 1e-03" />
      <joint name="waist_pitch_joint" />
    </body>
    <body name="left_wrist_pitch" pos="0 0 20">
      <inertial pos="0.0 0.0 0.0" mass="1e-03"
        diaginertia="1e-03 1e-03 1e-03" />
      <joint name="left_wrist_pitch_joint" />
    </body>
    <body name="left_wrist_yaw" pos="0 0 20">
      <inertial pos="0.0 0.0 0.0" mass="1e-03"
        diaginertia="1e-03 1e-03 1e-03" />
      <joint name="left_wrist_yaw_joint" />
    </body>
    <body name="right_wrist_pitch" pos="0 0 20">
      <inertial pos="0.0 0.0 0.0" mass="1e-03"
        diaginertia="1e-03 1e-03 1e-03" />
      <joint name="right_wrist_pitch_joint" />
    </body>
    <body name="right_wrist_yaw" pos="0 0 20">
      <inertial pos="0.0 0.0 0.0" mass="1e-03"
        diaginertia="1e-03 1e-03 1e-03" />
      <joint name="right_wrist_yaw_joint" />
    </body>
  </worldbody>

<actuator>
    <motor name="left_hip_pitch" joint="left_hip_pitch_joint" ctrlrange="-88 88" />
    <motor name="left_hip_roll" joint="left_hip_roll_joint" ctrlrange="-88 88" />
    <motor name="left_hip_yaw" joint="left_hip_yaw_joint" ctrlrange="-88 88" />
    <motor name="left_knee" joint="left_knee_joint" ctrlrange="-139 139" />
    <motor name="left_ankle_pitch" joint="left_ankle_pitch_joint" ctrlrange="-50 50" />
    <motor name="left_ankle_roll" joint="left_ankle_roll_joint" ctrlrange="-50 50" />

    <motor name="right_hip_pitch" joint="right_hip_pitch_joint" ctrlrange="-88 88" />
    <motor name="right_hip_roll" joint="right_hip_roll_joint" ctrlrange="-88 88" />
    <motor name="right_hip_yaw" joint="right_hip_yaw_joint" ctrlrange="-88 88" />
    <motor name="right_knee" joint="right_knee_joint" ctrlrange="-139 139" />
    <motor name="right_ankle_pitch" joint="right_ankle_pitch_joint" ctrlrange="-50 50" />
    <motor name="right_ankle_roll" joint="right_ankle_roll_joint" ctrlrange="-50 50" />

    <motor name="waist_yaw" joint="waist_yaw_joint" ctrlrange="-88 88" />
    <motor name="waist_roll" joint="waist_roll_joint" ctrlrange="-50 50" />
    <motor name="waist_pitch" joint="waist_pitch_joint" ctrlrange="-50 50" />

    <motor name="left_shoulder_pitch" joint="left_shoulder_pitch_joint" ctrlrange="-25 25" />
    <motor name="left_shoulder_roll" joint="left_shoulder_roll_joint" ctrlrange="-25 25" />
    <motor name="left_shoulder_yaw" joint="left_shoulder_yaw_joint" ctrlrange="-25 25" />
    <motor name="left_elbow" joint="left_elbow_joint" ctrlrange="-25 25" />
    <motor name="left_wrist_roll" joint="left_wrist_roll_joint" ctrlrange="-25 25" />
    <motor name="left_wrist_pitch" joint="left_wrist_pitch_joint" ctrlrange="-5 5" />
    <motor name="left_wrist_yaw" joint="left_wrist_yaw_joint" ctrlrange="-5 5" />

    <motor name="right_shoulder_pitch" joint="right_shoulder_pitch_joint" ctrlrange="-25 25" />
    <motor name="right_shoulder_roll" joint="right_shoulder_roll_joint" ctrlrange="-25 25" />
    <motor name="right_shoulder_yaw" joint="right_shoulder_yaw_joint" ctrlrange="-25 25" />
    <motor name="right_elbow" joint="right_elbow_joint" ctrlrange="-25 25" />
    <motor name="right_wrist_roll" joint="right_wrist_roll_joint" ctrlrange="-25 25" />
    <motor name="right_wrist_pitch" joint="right_wrist_pitch_joint" ctrlrange="-5 5" />
    <motor name="right_wrist_yaw" joint="right_wrist_yaw_joint" ctrlrange="-5 5" />
  </actuator>

<!--新增IMU -->
  <sensor>
    <jointpos name="left_hip_pitch_pos" joint="left_hip_pitch_joint" />
    <jointpos name="left_hip_roll_pos" joint="left_hip_roll_joint" />
    <jointpos name="left_hip_yaw_pos" joint="left_hip_yaw_joint" />
    <jointpos name="left_knee_pos" joint="left_knee_joint" />
    <jointpos name="left_ankle_pitch_pos" joint="left_ankle_pitch_joint" />
    <jointpos name="left_ankle_roll_pos" joint="left_ankle_roll_joint" />
    <jointpos name="right_hip_pitch_pos" joint="right_hip_pitch_joint" />
    <jointpos name="right_hip_roll_pos" joint="right_hip_roll_joint" />
    <jointpos name="right_hip_yaw_pos" joint="right_hip_yaw_joint" />
    <jointpos name="right_knee_pos" joint="right_knee_joint" />
    <jointpos name="right_ankle_pitch_pos" joint="right_ankle_pitch_joint" />
    <jointpos name="right_ankle_roll_pos" joint="right_ankle_roll_joint" />
    <jointpos name="waist_yaw_pos" joint="waist_yaw_joint" />
    <jointpos name="waist_roll_pos" joint="waist_roll_joint" />
    <jointpos name="waist_pitch_pos" joint="waist_pitch_joint" />
    <jointpos name="left_shoulder_pitch_pos" joint="left_shoulder_pitch_joint" />
    <jointpos name="left_shoulder_roll_pos" joint="left_shoulder_roll_joint" />
    <jointpos name="left_shoulder_yaw_pos" joint="left_shoulder_yaw_joint" />
    <jointpos name="left_elbow_pos" joint="left_elbow_joint" />
    <jointpos name="left_wrist_roll_pos" joint="left_wrist_roll_joint" />
    <jointpos name="left_wrist_pitch_pos" joint="left_wrist_pitch_joint" />
    <jointpos name="left_wrist_yaw_pos" joint="left_wrist_yaw_joint" />
    <jointpos name="right_shoulder_pitch_pos" joint="right_shoulder_pitch_joint" />
    <jointpos name="right_shoulder_roll_pos" joint="right_shoulder_roll_joint" />
    <jointpos name="right_shoulder_yaw_pos" joint="right_shoulder_yaw_joint" />
    <jointpos name="right_elbow_pos" joint="right_elbow_joint" />
    <jointpos name="right_wrist_roll_pos" joint="right_wrist_roll_joint" />
    <jointpos name="right_wrist_pitch_pos" joint="right_wrist_pitch_joint" />
    <jointpos name="right_wrist_yaw_pos" joint="right_wrist_yaw_joint" />

    <jointvel name="left_hip_pitch_vel" joint="left_hip_pitch_joint" />
    <jointvel name="left_hip_roll_vel" joint="left_hip_roll_joint" />
    <jointvel name="left_hip_yaw_vel" joint="left_hip_yaw_joint" />
    <jointvel name="left_knee_vel" joint="left_knee_joint" />
    <jointvel name="left_ankle_pitch_vel" joint="left_ankle_pitch_joint" />
    <jointvel name="left_ankle_roll_vel" joint="left_ankle_roll_joint" />
    <jointvel name="right_hip_pitch_vel" joint="right_hip_pitch_joint" />
    <jointvel name="right_hip_roll_vel" joint="right_hip_roll_joint" />
    <jointvel name="right_hip_yaw_vel" joint="right_hip_yaw_joint" />
    <jointvel name="right_knee_vel" joint="right_knee_joint" />
    <jointvel name="right_ankle_pitch_vel" joint="right_ankle_pitch_joint" />
    <jointvel name="right_ankle_roll_vel" joint="right_ankle_roll_joint" />
    <jointvel name="waist_yaw_vel" joint="waist_yaw_joint" />
    <jointvel name="waist_roll_vel" joint="waist_roll_joint" />
    <jointvel name="waist_pitch_vel" joint="waist_pitch_joint" />
    <jointvel name="left_shoulder_pitch_vel" joint="left_shoulder_pitch_joint" />
    <jointvel name="left_shoulder_roll_vel" joint="left_shoulder_roll_joint" />
    <jointvel name="left_shoulder_yaw_vel" joint="left_shoulder_yaw_joint" />
    <jointvel name="left_elbow_vel" joint="left_elbow_joint" />
    <jointvel name="left_wrist_roll_vel" joint="left_wrist_roll_joint" />
    <jointvel name="left_wrist_pitch_vel" joint="left_wrist_pitch_joint" />
    <jointvel name="left_wrist_yaw_vel" joint="left_wrist_yaw_joint" />
    <jointvel name="right_shoulder_pitch_vel" joint="right_shoulder_pitch_joint" />
    <jointvel name="right_shoulder_roll_vel" joint="right_shoulder_roll_joint" />
    <jointvel name="right_shoulder_yaw_vel" joint="right_shoulder_yaw_joint" />
    <jointvel name="right_elbow_vel" joint="right_elbow_joint" />
    <jointvel name="right_wrist_roll_vel" joint="right_wrist_roll_joint" />
    <jointvel name="right_wrist_pitch_vel" joint="right_wrist_pitch_joint" />
    <jointvel name="right_wrist_yaw_vel" joint="right_wrist_yaw_joint" />

    <jointactuatorfrc name="left_hip_pitch_torque" joint="left_hip_pitch_joint" />
    <jointactuatorfrc name="left_hip_roll_torque" joint="left_hip_roll_joint" />
    <jointactuatorfrc name="left_hip_yaw_torque" joint="left_hip_yaw_joint" />
    <jointactuatorfrc name="left_knee_torque" joint="left_knee_joint" />
    <jointactuatorfrc name="left_ankle_pitch_torque" joint="left_ankle_pitch_joint" />
    <jointactuatorfrc name="left_ankle_roll_torque" joint="left_ankle_roll_joint" />
    <jointactuatorfrc name="right_hip_pitch_torque" joint="right_hip_pitch_joint" />
    <jointactuatorfrc name="right_hip_roll_torque" joint="right_hip_roll_joint" />
    <jointactuatorfrc name="right_hip_yaw_torque" joint="right_hip_yaw_joint" />
    <jointactuatorfrc name="right_knee_torque" joint="right_knee_joint" />
    <jointactuatorfrc name="right_ankle_pitch_torque" joint="right_ankle_pitch_joint" />
    <jointactuatorfrc name="right_ankle_roll_torque" joint="right_ankle_roll_joint" />
    <jointactuatorfrc name="waist_yaw_torque" joint="waist_yaw_joint" />
    <jointactuatorfrc name="waist_roll_torque" joint="waist_roll_joint" />
    <jointactuatorfrc name="waist_pitch_torque" joint="waist_pitch_joint" />
    <jointactuatorfrc name="left_shoulder_pitch_torque" joint="left_shoulder_pitch_joint" />
    <jointactuatorfrc name="left_shoulder_roll_torque" joint="left_shoulder_roll_joint" />
    <jointactuatorfrc name="left_shoulder_yaw_torque" joint="left_shoulder_yaw_joint" />
    <jointactuatorfrc name="left_elbow_torque" joint="left_elbow_joint" />
    <jointactuatorfrc name="left_wrist_roll_torque" joint="left_wrist_roll_joint" />
    <jointactuatorfrc name="left_wrist_pitch_torque" joint="left_wrist_pitch_joint" />
    <jointactuatorfrc name="left_wrist_yaw_torque" joint="left_wrist_yaw_joint" />
    <jointactuatorfrc name="right_shoulder_pitch_torque" joint="right_shoulder_pitch_joint" />
    <jointactuatorfrc name="right_shoulder_roll_torque" joint="right_shoulder_roll_joint" />
    <jointactuatorfrc name="right_shoulder_yaw_torque" joint="right_shoulder_yaw_joint" />
    <jointactuatorfrc name="right_elbow_torque" joint="right_elbow_joint" />
    <jointactuatorfrc name="right_wrist_roll_torque" joint="right_wrist_roll_joint" />
    <jointactuatorfrc name="right_wrist_pitch_torque" joint="right_wrist_pitch_joint" />
    <jointactuatorfrc name="right_wrist_yaw_torque" joint="right_wrist_yaw_joint" />

    <framequat name="imu_quat" objtype="site" objname="imu" />
    <gyro name="imu_gyro" site="imu" />
    <accelerometer name="imu_acc" site="imu" />

    <framepos name="frame_pos" objtype="site" objname="imu" />
    <framelinvel name="frame_vel" objtype="site" objname="imu" />

    <framequat name="secondary_imu_quat" objtype="site" objname="secondary_imu" />
    <gyro name="secondary_imu_gyro" site="secondary_imu" noise="5e-4" cutoff="34.9"/>
    <accelerometer name="secondary_imu_acc" site="secondary_imu" noise="1e-2" cutoff="157"/>
  </sensor>

</mujoco>
